Traceback (most recent call last):
  File "/usr/local/lib/python3.10/dist-packages/jupyter_cache/executors/utils.py", line 58, in single_nb_execution
    executenb(
  File "/usr/local/lib/python3.10/dist-packages/nbclient/client.py", line 1305, in execute
    return NotebookClient(nb=nb, resources=resources, km=km, **kwargs).execute()
  File "/usr/local/lib/python3.10/dist-packages/jupyter_core/utils/__init__.py", line 166, in wrapped
    return loop.run_until_complete(inner)
  File "/usr/lib/python3.10/asyncio/base_events.py", line 649, in run_until_complete
    return future.result()
  File "/usr/local/lib/python3.10/dist-packages/nbclient/client.py", line 705, in async_execute
    await self.async_execute_cell(
  File "/usr/local/lib/python3.10/dist-packages/nbclient/client.py", line 1058, in async_execute_cell
    await self._check_raise_for_error(cell, cell_index, exec_reply)
  File "/usr/local/lib/python3.10/dist-packages/nbclient/client.py", line 914, in _check_raise_for_error
    raise CellExecutionError.from_cell_and_msg(cell, exec_reply_content)
nbclient.exceptions.CellExecutionError: An error occurred while executing the following cell:
------------------
df['species'].value_counts()
------------------


[0;31m[0m
[0;31mKeyError[0mTraceback (most recent call last)
[0;32m/usr/local/lib/python3.10/dist-packages/pandas/core/indexes/base.py[0m in [0;36mget_loc[0;34m(self, key, method, tolerance)[0m
[1;32m   3801[0m             [0;32mtry[0m[0;34m:[0m[0;34m[0m[0;34m[0m[0m
[0;32m-> 3802[0;31m                 [0;32mreturn[0m [0mself[0m[0;34m.[0m[0m_engine[0m[0;34m.[0m[0mget_loc[0m[0;34m([0m[0mcasted_key[0m[0;34m)[0m[0;34m[0m[0;34m[0m[0m
[0m[1;32m   3803[0m             [0;32mexcept[0m [0mKeyError[0m [0;32mas[0m [0merr[0m[0;34m:[0m[0;34m[0m[0;34m[0m[0m

[0;32m/usr/local/lib/python3.10/dist-packages/pandas/_libs/index.pyx[0m in [0;36mpandas._libs.index.IndexEngine.get_loc[0;34m()[0m

[0;32m/usr/local/lib/python3.10/dist-packages/pandas/_libs/index.pyx[0m in [0;36mpandas._libs.index.IndexEngine.get_loc[0;34m()[0m

[0;32mpandas/_libs/hashtable_class_helper.pxi[0m in [0;36mpandas._libs.hashtable.PyObjectHashTable.get_item[0;34m()[0m

[0;32mpandas/_libs/hashtable_class_helper.pxi[0m in [0;36mpandas._libs.hashtable.PyObjectHashTable.get_item[0;34m()[0m

[0;31mKeyError[0m: 'species'

The above exception was the direct cause of the following exception:

[0;31mKeyError[0mTraceback (most recent call last)
[0;32m<ipython-input-3-1a8c322653e2>[0m in [0;36m<cell line: 1>[0;34m()[0m
[0;32m----> 1[0;31m [0mdf[0m[0;34m[[0m[0;34m'species'[0m[0;34m][0m[0;34m.[0m[0mvalue_counts[0m[0;34m([0m[0;34m)[0m[0;34m[0m[0;34m[0m[0m
[0m
[0;32m/usr/local/lib/python3.10/dist-packages/pandas/core/frame.py[0m in [0;36m__getitem__[0;34m(self, key)[0m
[1;32m   3805[0m             [0;32mif[0m [0mself[0m[0;34m.[0m[0mcolumns[0m[0;34m.[0m[0mnlevels[0m [0;34m>[0m [0;36m1[0m[0;34m:[0m[0;34m[0m[0;34m[0m[0m
[1;32m   3806[0m                 [0;32mreturn[0m [0mself[0m[0;34m.[0m[0m_getitem_multilevel[0m[0;34m([0m[0mkey[0m[0;34m)[0m[0;34m[0m[0;34m[0m[0m
[0;32m-> 3807[0;31m             [0mindexer[0m [0;34m=[0m [0mself[0m[0;34m.[0m[0mcolumns[0m[0;34m.[0m[0mget_loc[0m[0;34m([0m[0mkey[0m[0;34m)[0m[0;34m[0m[0;34m[0m[0m
[0m[1;32m   3808[0m             [0;32mif[0m [0mis_integer[0m[0;34m([0m[0mindexer[0m[0;34m)[0m[0;34m:[0m[0;34m[0m[0;34m[0m[0m
[1;32m   3809[0m                 [0mindexer[0m [0;34m=[0m [0;34m[[0m[0mindexer[0m[0;34m][0m[0;34m[0m[0;34m[0m[0m

[0;32m/usr/local/lib/python3.10/dist-packages/pandas/core/indexes/base.py[0m in [0;36mget_loc[0;34m(self, key, method, tolerance)[0m
[1;32m   3802[0m                 [0;32mreturn[0m [0mself[0m[0;34m.[0m[0m_engine[0m[0;34m.[0m[0mget_loc[0m[0;34m([0m[0mcasted_key[0m[0;34m)[0m[0;34m[0m[0;34m[0m[0m
[1;32m   3803[0m             [0;32mexcept[0m [0mKeyError[0m [0;32mas[0m [0merr[0m[0;34m:[0m[0;34m[0m[0;34m[0m[0m
[0;32m-> 3804[0;31m                 [0;32mraise[0m [0mKeyError[0m[0;34m([0m[0mkey[0m[0;34m)[0m [0;32mfrom[0m [0merr[0m[0;34m[0m[0;34m[0m[0m
[0m[1;32m   3805[0m             [0;32mexcept[0m [0mTypeError[0m[0;34m:[0m[0;34m[0m[0;34m[0m[0m
[1;32m   3806[0m                 [0;31m# If we have a listlike key, _check_indexing_error will raise[0m[0;34m[0m[0;34m[0m[0m

[0;31mKeyError[0m: 'species'

