Traceback (most recent call last):
  File "/usr/local/lib/python3.10/dist-packages/jupyter_cache/executors/utils.py", line 58, in single_nb_execution
    executenb(
  File "/usr/local/lib/python3.10/dist-packages/nbclient/client.py", line 1305, in execute
    return NotebookClient(nb=nb, resources=resources, km=km, **kwargs).execute()
  File "/usr/local/lib/python3.10/dist-packages/jupyter_core/utils/__init__.py", line 166, in wrapped
    return loop.run_until_complete(inner)
  File "/usr/lib/python3.10/asyncio/base_events.py", line 649, in run_until_complete
    return future.result()
  File "/usr/local/lib/python3.10/dist-packages/nbclient/client.py", line 705, in async_execute
    await self.async_execute_cell(
  File "/usr/local/lib/python3.10/dist-packages/nbclient/client.py", line 1058, in async_execute_cell
    await self._check_raise_for_error(cell, cell_index, exec_reply)
  File "/usr/local/lib/python3.10/dist-packages/nbclient/client.py", line 914, in _check_raise_for_error
    raise CellExecutionError.from_cell_and_msg(cell, exec_reply_content)
nbclient.exceptions.CellExecutionError: An error occurred while executing the following cell:
------------------
X_train, X_test, y_train, y_test = train_test_split(X, y, test_size=0.20, random_state=0, stratify=y)
------------------


[0;31m[0m
[0;31mNameError[0mTraceback (most recent call last)
[0;32m<ipython-input-15-fa1569143e1a>[0m in [0;36m<cell line: 1>[0;34m()[0m
[0;32m----> 1[0;31m [0mX_train[0m[0;34m,[0m [0mX_test[0m[0;34m,[0m [0my_train[0m[0;34m,[0m [0my_test[0m [0;34m=[0m [0mtrain_test_split[0m[0;34m([0m[0mX[0m[0;34m,[0m [0my[0m[0;34m,[0m [0mtest_size[0m[0;34m=[0m[0;36m0.20[0m[0;34m,[0m [0mrandom_state[0m[0;34m=[0m[0;36m0[0m[0;34m,[0m [0mstratify[0m[0;34m=[0m[0my[0m[0;34m)[0m[0;34m[0m[0;34m[0m[0m
[0m
[0;31mNameError[0m: name 'train_test_split' is not defined

